Workbook

Sheet suppliers_coldchain
A1: supplier_id | B1: supplier_name | C1: supplier_type | D1: country | E1: lead_time_days | F1: payment_terms_days | G1: service_level | H1: active_flag | I1: risk_score | J1: primary_contact
A2: SUP00001 | B2: Supplier 001 | C2: Importer | D2: UK | E2: 14 | F2: 15 | G2: B | H2: N | I2: 80 | J2: contact001@example.com
A3: SUP00002 | B3: Supplier 002 | C3: Local Partner | D3: UK | E3: 7 | F3: 45 | G3: A | H3: N | I3: 40 | J3: contact002@example.com
A4: SUP00003 | B4: Supplier 003 | C4: Primary Manufacturer | D4: UAE | E4: 9 | F4: 60 | G4: C | H4: N | I4: 61 | J4: contact003@example.com
A5: SUP00004 | B5: Supplier 004 | C5: Importer | D5: South Africa | E5: 19 | F5: 60 | G5: A | H5: Y | I5: 64 | J5: contact004@example.com
A6: SUP00005 | B6: Supplier 005 | C6: Local Partner | D6: Morocco | E6: 6 | F6: 30 | G6: B | H6: N | I6: 63 | J6: contact005@example.com
A7: SUP00006 | B7: Supplier 006 | C7: Importer | D7: Egypt | E7: 6 | F7: 45 | G7: B | H7: Y | I7: 68 | J7: contact006@example.com
A8: SUP00007 | B8: Supplier 007 | C8: Distributor | D8: South Africa | E8: 13 | F8: 60 | G8: C | H8: Y | I8: 46 | J8: contact007@example.com
A9: SUP00008 | B9: Supplier 008 | C9: Distributor | D9: Ghana | E9: 11 | F9: 45 | G9: A | H9: Y | I9: 64 | J9: contact008@example.com
A10: SUP00009 | B10: Supplier 009 | C10: Distributor | D10: South Africa | E10: 10 | F10: 30 | G10: A | H10: Y | I10: 34 | J10: contact009@example.com
A11: SUP00010 | B11: Supplier 010 | C11: Primary Manufacturer | D11: Nigeria | E11: 8 | F11: 15 | G11: A | H11: Y | I11: 84 | J11: contact010@example.com
A12: SUP00011 | B12: Supplier 011 | C12: Primary Manufacturer | D12: UAE | E12: 17 | F12: 60 | G12: C | H12: N | I12: 69 | J12: contact011@example.com
A13: SUP00012 | B13: Supplier 012 | C13: Local Partner | D13: Nigeria | E13: 3 | F13: 60 | G13: B | H13: Y | I13: 55 | J13: contact012@example.com
... A121: SUP00120 | B121: Supplier 120 | C121: Primary Manufacturer | D121: Nigeria | E121: 4 | F121: 45 | G121: A | H121: Y | I121: 66 | J121: contact120@example.com

Sheet products_coldchain
A1: product_id | B1: sku | C1: product_name | D1: category | E1: uom | F1: primary_supplier_id | G1: storage_temp_min_c | H1: storage_temp_max_c | I1: shelf_life_days | J1: standard_cost | K1: standard_price | L1: fefo_required | M1: active_flag
A2: PRD00001 | B2: CC-0001 | C2: Baby Food Item 001 | D2: Baby Food | E2: Jar | F2: SUP00034 | G2: 4 | H2: 8 | I2: 45 | J2: 13.36 | K2: 20.72 | L2: N | M2: Y
A3: PRD00002 | B3: CC-0002 | C3: Premium Cheese Item 002 | D3: Premium Cheese | E3: Kg | F3: SUP00012 | G3: 2 | H3: 8 | I3: 120 | J3: 5.85 | K3: 14.27 | L3: Y | M3: Y
A4: PRD00003 | B4: CC-0003 | C4: Herbs Item 003 | D4: Herbs | E4: Bundle | F4: SUP00015 | G4: 1 | H4: 6 | I4: 45 | J4: 15.41 | K4: 31.16 | L4: Y | M4: Y
A5: PRD00004 | B5: CC-0004 | C5: Ready Meal Item 004 | D5: Ready Meal | E5: Tray | F5: SUP00036 | G5: 0 | H5: 5 | I5: 60 | J5: 4.96 | K5: 7.2 | L5: N | M5: Y
A6: PRD00005 | B6: CC-0005 | C6: Seafood Item 005 | D6: Seafood | E6: Kg | F6: SUP00088 | G6: -2 | H6: 4 | I6: 90 | J6: 2.05 | K6: 2.79 | L6: N | M6: Y
A7: PRD00006 | B7: CC-0006 | C7: Ready Meal Item 006 | D7: Ready Meal | E7: Tray | F7: SUP00090 | G7: 0 | H7: 5 | I7: 30 | J7: 8.14 | K7: 10.99 | L7: N | M7: Y
A8: PRD00007 | B8: CC-0007 | C8: Herbs Item 007 | D8: Herbs | E8: Bundle | F8: SUP00084 | G8: 1 | H8: 6 | I8: 45 | J8: 12.87 | K8: 25.48 | L8: Y | M8: Y
A9: PRD00008 | B9: CC-0008 | C9: Fresh Dairy Item 008 | D9: Fresh Dairy | E9: Kg | F9: SUP00003 | G9: 2 | H9: 6 | I9: 14 | J9: 15.41 | K9: 21.55 | L9: Y | M9: Y
A10: PRD00009 | B10: CC-0009 | C10: Seafood Item 009 | D10: Seafood | E10: Kg | F10: SUP00023 | G10: -2 | H10: 4 | I10: 10 | J10: 3.74 | K10: 8.63 | L10: Y | M10: Y
A11: PRD00010 | B11: CC-0010 | C11: Ready Meal Item 010 | D11: Ready Meal | E11: Tray | F11: SUP00096 | G11: 0 | H11: 5 | I11: 60 | J11: 4.91 | K11: 6.85 | L11: Y | M11: Y
A12: PRD00011 | B12: CC-0011 | C12: Chilled Juice Item 011 | D12: Chilled Juice | E12: Litre | F12: SUP00082 | G12: 2 | H12: 8 | I12: 7 | J12: 4.06 | K12: 6.59 | L12: N | M12: Y
A13: PRD00012 | B13: CC-0012 | C13: Fresh Dairy Item 012 | D13: Fresh Dairy | E13: Kg | F13: SUP00014 | G13: 2 | H13: 6 | I13: 21 | J13: 3.14 | K13: 4.7 | L13: Y | M13: Y
... A181: PRD00180 | B181: CC-0180 | C181: Frozen Dessert Item 180 | D181: Frozen Dessert | E181: Pack | F181: SUP00110 | G181: -18 | H181: -10 | I181: 10 | J181: 14.43 | K181: 34.18 | L181: Y | M181: Y

Sheet purchase_orders_coldchain
A1: po_id | B1: supplier_id | C1: warehouse_id | D1: warehouse_name | E1: order_date | F1: expected_delivery_date | G1: status | H1: ordered_by | I1: currency | J1: shipping_cost | K1: priority
A2: PO000001 | B2: SUP00061 | C2: WH-ABJ-01 | D2: Abuja Distribution Hub | E2: 45685.255 | F2: 45690.255 | G2: Cancelled | H2: A. Yusuf | I2: NGN | J2: 52.81 | K2: Normal
A3: PO000002 | B3: SUP00101 | C3: WH-LAG-01 | D3: Lagos North Cold Hub | E3: 45675.255 | F3: 45677.255 | G3: Open | H3: I. Chukwu | I3: NGN | J3: 170.13 | K3: Normal
A4: PO000003 | B4: SUP00089 | C4: WH-AWK-01 | D4: Awka Micro Hub | E4: 45660.737 | F4: 45668.737 | G4: Partial | H4: I. Chukwu | I4: USD | J4: 175.86 | K4: Normal
A5: PO000004 | B5: SUP00004 | C5: WH-JOS-01 | D5: Jos Altitude Hub | E5: 45668.691 | F5: 45686.691 | G5: Received | H5: T. Bello | I5: NGN | J5: 159.19 | K5: Normal
A6: PO000005 | B6: SUP00059 | C6: WH-LAG-02 | D6: Lagos South Cold Hub | E6: 45686.325 | F6: 45691.325 | G6: Received | H6: M. Okafor | I6: NGN | J6: 298.77 | K6: Normal
A7: PO000006 | B7: SUP00077 | C7: WH-BEN-01 | D7: Benin City Hub | E7: 45711.177 | F7: 45722.177 | G7: Cancelled | H7: S. Ibrahim | I7: NGN | J7: 191.67 | K7: Normal
A8: PO000007 | B8: SUP00079 | C8: WH-ABJ-01 | D8: Abuja Distribution Hub | E8: 45719.591 | F8: 45731.591 | G8: Received | H8: A. Yusuf | I8: NGN | J8: 176.05 | K8: Urgent
A9: PO000008 | B9: SUP00083 | C9: WH-ABJ-01 | D9: Abuja Distribution Hub | E9: 45666.835 | F9: 45684.835 | G9: Partial | H9: S. Ibrahim | I9: NGN | J9: 88.26 | K9: Normal
A10: PO000009 | B10: SUP00051 | C10: WH-LAG-01 | D10: Lagos North Cold Hub | E10: 45659.464 | F10: 45679.464 | G10: Received | H10: I. Chukwu | I10: USD | J10: 165.31 | K10: Urgent
A11: PO000010 | B11: SUP00048 | C11: WH-ENU-01 | D11: Enugu Regional Hub | E11: 45667.774 | F11: 45675.774 | G11: Received | H11: T. Bello | I11: NGN | J11: 275.54 | K11: Normal
A12: PO000011 | B12: SUP00043 | C12: WH-IBA-01 | D12: Ibadan Regional Hub | E12: 45700.061 | F12: 45705.061 | G12: Open | H12: M. Okafor | I12: NGN | J12: 239.87 | K12: Urgent
A13: PO000012 | B13: SUP00027 | C13: WH-ABJ-01 | D13: Abuja Distribution Hub | E13: 45703.656 | F13: 45707.656 | G13: Partial | H13: S. Ibrahim | I13: NGN | J13: 157.83 | K13: Urgent
... A151: PO000150 | B151: SUP00117 | C151: WH-BEN-01 | D151: Benin City Hub | E151: 45681.339 | F151: 45690.339 | G151: Received | H151: T. Bello | I151: USD | J151: 45.24 | K151: Normal

Sheet purchase_order_lines_coldchain
A1: po_line_id | B1: po_id | C1: supplier_id | D1: warehouse_id | E1: order_date | F1: expected_delivery_date | G1: product_id | H1: ordered_qty | I1: unit_cost | J1: discount_pct | K1: line_total | L1: line_total_actual | M1: line_total_Check | N1: line_status
A2: POL000001 | B2: PO000001 | C2: SUP00061 | D2: WH-ABJ-01 | E2: 45685.255 | F2: 45690.255 | G2: PRD00161 | H2: 85 | I2: 3.75 | J2: 2.5 | K2: 310.78 | L2: =ROUND((H2*I2)-(J2/100)*(H2*I2),2) -> 310.78 | M2: =IF(K2=L2,"Pass",IF(K2=L2-0.01,"Pass","Investigate")) -> Pass | N2: Open
A3: POL000002 | B3: PO000001 | C3: SUP00061 | D3: WH-ABJ-01 | E3: 45685.255 | F3: 45690.255 | G3: PRD00161 | H3: 96 | I3: 3.57 | J3: 0 | K3: 342.72 | L3: =ROUND((H3*I3)-(J3/100)*(H3*I3),2) -> 342.72 | M3: =IF(K3=L3,"Pass",IF(K3=L3-0.01,"Pass","Investigate")) -> Pass | N3: Open
A4: POL000003 | B4: PO000001 | C4: SUP00061 | D4: WH-ABJ-01 | E4: 45685.255 | F4: 45690.255 | G4: PRD00161 | H4: 169 | I4: 4.05 | J4: 0 | K4: 684.45 | L4: =ROUND((H4*I4)-(J4/100)*(H4*I4),2) -> 684.45 | M4: =IF(K4=L4,"Pass",IF(K4=L4-0.01,"Pass","Investigate")) -> Pass | N4: Closed
A5: POL000004 | B5: PO000002 | C5: SUP00101 | D5: WH-LAG-01 | E5: 45675.255 | F5: 45677.255 | G5: PRD00067 | H5: 144 | I5: 2.42 | J5: 5 | K5: 331.06 | L5: =ROUND((H5*I5)-(J5/100)*(H5*I5),2) -> 331.06 | M5: =IF(K5=L5,"Pass",IF(K5=L5-0.01,"Pass","Investigate")) -> Pass | N5: Open
A6: POL000005 | B6: PO000002 | C6: SUP00101 | D6: WH-LAG-01 | E6: 45675.255 | F6: 45677.255 | G6: PRD00033 | H6: 237 | I6: 13.16 | J6: 0 | K6: 3118.92 | L6: =ROUND((H6*I6)-(J6/100)*(H6*I6),2) -> 3118.92 | M6: =IF(K6=L6,"Pass",IF(K6=L6-0.01,"Pass","Investigate")) -> Pass | N6: Open
A7: POL000006 | B7: PO000003 | C7: SUP00089 | D7: WH-AWK-01 | E7: 45660.737 | F7: 45668.737 | G7: PRD00178 | H7: 64 | I7: 3.96 | J7: 7.5 | K7: 234.43 | L7: =ROUND((H7*I7)-(J7/100)*(H7*I7),2) -> 234.43 | M7: =IF(K7=L7,"Pass",IF(K7=L7-0.01,"Pass","Investigate")) -> Pass | N7: Open
A8: POL000007 | B8: PO000003 | C8: SUP00089 | D8: WH-AWK-01 | E8: 45660.737 | F8: 45668.737 | G8: PRD00011 | H8: 156 | I8: 4.15 | J8: 10 | K8: 582.66 | L8: =ROUND((H8*I8)-(J8/100)*(H8*I8),2) -> 582.66 | M8: =IF(K8=L8,"Pass",IF(K8=L8-0.01,"Pass","Investigate")) -> Pass | N8: Open
A9: POL000008 | B9: PO000004 | C9: SUP00004 | D9: WH-JOS-01 | E9: 45668.691 | F9: 45686.691 | G9: PRD00007 | H9: 105 | I9: 13.26 | J9: 0 | K9: 1392.3 | L9: =ROUND((H9*I9)-(J9/100)*(H9*I9),2) -> 1392.3 | M9: =IF(K9=L9,"Pass",IF(K9=L9-0.01,"Pass","Investigate")) -> Pass | N9: Closed
A10: POL000009 | B10: PO000004 | C10: SUP00004 | D10: WH-JOS-01 | E10: 45668.691 | F10: 45686.691 | G10: PRD00058 | H10: 104 | I10: 6.88 | J10: 0 | K10: 715.52 | L10: =ROUND((H10*I10)-(J10/100)*(H10*I10),2) -> 715.52 | M10: =IF(K10=L10,"Pass",IF(K10=L10-0.01,"Pass","Investigate")) -> Pass | N10: Closed
A11: POL000010 | B11: PO000004 | C11: SUP00004 | D11: WH-JOS-01 | E11: 45668.691 | F11: 45686.691 | G11: PRD00141 | H11: 96 | I11: 10.54 | J11: 10 | K11: 910.66 | L11: =ROUND((H11*I11)-(J11/100)*(H11*I11),2) -> 910.66 | M11: =IF(K11=L11,"Pass",IF(K11=L11-0.01,"Pass","Investigate")) -> Pass | N11: Partial
A12: POL000011 | B12: PO000005 | C12: SUP00059 | D12: WH-LAG-02 | E12: 45686.325 | F12: 45691.325 | G12: PRD00170 | H12: 29 | I12: 9.98 | J12: 10 | K12: 260.48 | L12: =ROUND((H12*I12)-(J12/100)*(H12*I12),2) -> 260.48 | M12: =IF(K12=L12,"Pass",IF(K12=L12-0.01,"Pass","Investigate")) -> Pass | N12: Partial
A13: POL000012 | B13: PO000005 | C13: SUP00059 | D13: WH-LAG-02 | E13: 45686.325 | F13: 45691.325 | G13: PRD00147 | H13: 130 | I13: 16.2 | J13: 10 | K13: 1895.4 | L13: =ROUND((H13*I13)-(J13/100)*(H13*I13),2) -> 1895.4 | M13: =IF(K13=L13,"Pass",IF(K13=L13-0.01,"Pass","Investigate")) -> Pass | N13: Closed
... A421: POL000420 | B421: PO000150 | C421: SUP00117 | D421: WH-BEN-01 | E421: 45681.339 | F421: 45690.339 | G421: PRD00064 | H421: 123 | I421: 2.8 | J421: 10 | K421: 309.96 | L421: =ROUND((H421*I421)-(J421/100)*(H421*I421),2) -> 309.96 | M421: =IF(K421=L421,"Pass",IF(K421=L421-0.01,"Pass","Investigate")) -> Pass | N421: Open

Sheet stock_movements_coldchain
A1: movement_id | B1: movement_date | C1: movement_type | D1: warehouse_id | E1: product_id | F1: po_line_id | G1: reference_id | H1: missing_reference_id_check | I1: reference_id_actual | J1: lot_number | K1: quantity | L1: signed_qty | M1: unit_cost | N1: movement_value | O1: temperature_c | P1: reason
A2: MOV0000001 | B2: 45719.491 | C2: Receipt | D2: WH-PHC-01 | E2: PRD00124 | F2: POL000312 | G2: PO000111 | H2: {=IF(AND(G2="", C2="Receipt"), _xlfn.XLOOKUP(1, (purchase_order_lines_coldchain!A2:A1000 = F2) * (purchase_order_lines_coldchain!G2:G1000 = E2) * (purchase_order_lines_coldchain!D2:D1000 = D2), purchase_order_lines_coldchain!B$2:B$1000, _xlfn.XLOOKUP(F2,purchase_order_lines_coldchain!A$2:A1000, purchase_order_lines_coldchain!B$2:B1000)), "")} | I2: =G2 & H2 -> PO000111 | J2: LOT-124-000001 | K2: 89 | L2: 89 | M2: 15.19 | N2: 1351.91 | O2: 0.8 | P2: Supplier_Delivery
A3: MOV0000002 | B3: 45725.942 | C3: Receipt | D3: WH-ENU-01 | E3: PRD00043 | F3: POL000073 | G3: PO000026 | H3: {=IF(AND(G3="", C3="Receipt"), _xlfn.XLOOKUP(1, (purchase_order_lines_coldchain!A3:A1001 = F3) * (purchase_order_lines_coldchain!G3:G1001 = E3) * (purchase_order_lines_coldchain!D3:D1001 = D3), purchase_order_lines_coldchain!B$2:B$1000, _xlfn.XLOOKUP(F3,purchase_order_lines_coldchain!A$2:A1001, purchase_order_lines_coldchain!B$2:B1001)), "")} | I3: =G3 & H3 -> PO000026 | J3: LOT-043-000002 | K3: 148 | L3: 148 | M3: 13 | N3: 1924 | O3: 4.5 | P3: Supplier_Delivery
A4: MOV0000003 | B4: 45706.944 | C4: Receipt | D4: WH-AWK-01 | E4: PRD00075 | F4: POL000128 | G4: PO000046 | H4: {=IF(AND(G4="", C4="Receipt"), _xlfn.XLOOKUP(1, (purchase_order_lines_coldchain!A4:A1002 = F4) * (purchase_order_lines_coldchain!G4:G1002 = E4) * (purchase_order_lines_coldchain!D4:D1002 = D4), purchase_order_lines_coldchain!B$2:B$1000, _xlfn.XLOOKUP(F4,purchase_order_lines_coldchain!A$2:A1002, purchase_order_lines_coldchain!B$2:B1002)), "")} | I4: =G4 & H4 -> PO000046 | J4: LOT-075-000003 | K4: 44 | L4: 44 | M4: 11.87 | N4: 522.28 | O4: 7.6 | P4: Supplier_Delivery
A5: MOV0000004 | B5: 45733.142 | C5: Receipt | D5: WH-PHC-01 | E5: PRD00066 | F5: POL000138 | G5: PO000050 | H5: {=IF(AND(G5="", C5="Receipt"), _xlfn.XLOOKUP(1, (purchase_order_lines_coldchain!A5:A1003 = F5) * (purchase_order_lines_coldchain!G5:G1003 = E5) * (purchase_order_lines_coldchain!D5:D1003 = D5), purchase_order_lines_coldchain!B$2:B$1000, _xlfn.XLOOKUP(F5,purchase_order_lines_coldchain!A$2:A1003, purchase_order_lines_coldchain!B$2:B1003)), "")} | I5: =G5 & H5 -> PO000050 | J5: LOT-066-000004 | K5: 181 | L5: 181 | M5: 4.88 | N5: 883.28 | O5: 6 | P5: Supplier_Delivery
A6: MOV0000005 | B6: 45711.088 | C6: Receipt | D6: WH-ENU-01 | E6: PRD00066 | F6: POL000156 | G6: PO000056 | H6: {=IF(AND(G6="", C6="Receipt"), _xlfn.XLOOKUP(1, (purchase_order_lines_coldchain!A6:A1004 = F6) * (purchase_order_lines_coldchain!G6:G1004 = E6) * (purchase_order_lines_coldchain!D6:D1004 = D6), purchase_order_lines_coldchain!B$2:B$1000, _xlfn.XLOOKUP(F6,purchase_order_lines_coldchain!A$2:A1004, purchase_order_lines_coldchain!B$2:B1004)), "")} | I6: =G6 & H6 -> PO000056 | J6: LOT-066-000005 | K6: 117 | L6: 117 | M6: 4.58 | N6: 535.86 | O6: 7.6 | P6: Supplier_Delivery
A7: MOV0000006 | B7: 45671.68 | C7: Receipt | D7: WH-ENU-01 | E7: PRD00011 | F7: POL000151 | G7: PO000054 | H7: {=IF(AND(G7="", C7="Receipt"), _xlfn.XLOOKUP(1, (purchase_order_lines_coldchain!A7:A1005 = F7) * (purchase_order_lines_coldchain!G7:G1005 = E7) * (purchase_order_lines_coldchain!D7:D1005 = D7), purchase_order_lines_coldchain!B$2:B$1000, _xlfn.XLOOKUP(F7,purchase_order_lines_coldchain!A$2:A1005, purchase_order_lines_coldchain!B$2:B1005)), "")} | I7: =G7 & H7 -> PO000054 | J7: LOT-011-000006 | K7: 42 | L7: 42 | M7: 3.97 | N7: 166.74 | O7: 4.8 | P7: Supplier_Delivery
A8: MOV0000007 | B8: 45709.894 | C8: Receipt | D8: WH-PHC-01 | E8: PRD00107 | F8: POL000289 | G8: PO000103 | H8: {=IF(AND(G8="", C8="Receipt"), _xlfn.XLOOKUP(1, (purchase_order_lines_coldchain!A8:A1006 = F8) * (purchase_order_lines_coldchain!G8:G1006 = E8) * (purchase_order_lines_coldchain!D8:D1006 = D8), purchase_order_lines_coldchain!B$2:B$1000, _xlfn.XLOOKUP(F8,purchase_order_lines_coldchain!A$2:A1006, purchase_order_lines_coldchain!B$2:B1006)), "")} | I8: =G8 & H8 -> PO000103 | J8: LOT-107-000007 | K8: 47 | L8: 47 | M8: 11.56 | N8: 543.32 | O8: 2.8 | P8: Supplier_Delivery
A9: MOV0000008 | B9: 45707.269 | C9: Receipt | D9: WH-IBA-01 | E9: PRD00118 | F9: POL000028 | G9: PO000011 | H9: {=IF(AND(G9="", C9="Receipt"), _xlfn.XLOOKUP(1, (purchase_order_lines_coldchain!A9:A1007 = F9) * (purchase_order_lines_coldchain!G9:G1007 = E9) * (purchase_order_lines_coldchain!D9:D1007 = D9), purchase_order_lines_coldchain!B$2:B$1000, _xlfn.XLOOKUP(F9,purchase_order_lines_coldchain!A$2:A1007, purchase_order_lines_coldchain!B$2:B1007)), "")} | I9: =G9 & H9 -> PO000011 | J9: LOT-118-000008 | K9: 123 | L9: 123 | M9: 10.55 | N9: 1297.65 | O9: 7.8 | P9: Supplier_Delivery
A10: MOV0000009 | B10: 45679.232 | C10: Receipt | D10: WH-KAD-01 | E10: PRD00080 | F10: POL000162 | G10: PO000058 | H10: {=IF(AND(G10="", C10="Receipt"), _xlfn.XLOOKUP(1, (purchase_order_lines_coldchain!A10:A1008 = F10) * (purchase_order_lines_coldchain!G10:G1008 = E10) * (purchase_order_lines_coldchain!D10:D1008 = D10), purchase_order_lines_coldchain!B$2:B$1000, _xlfn.XLOOKUP(F10,purchase_order_lines_coldchain!A$2:A1008, purchase_order_lines_coldchain!B$2:B1008)), "")} | I10: =G10 & H10 -> PO000058 | J10: LOT-080-000009 | K10: 209 | L10: 209 | M10: 6.77 | N10: 1414.93 | O10: 6.6 | P10: Supplier_Delivery
A11: MOV0000010 | B11: 45701.304 | C11: Receipt | D11: WH-IBA-01 | E11: PRD00144 | F11: POL000327 | G11: PO000116 | H11: {=IF(AND(G11="", C11="Receipt"), _xlfn.XLOOKUP(1, (purchase_order_lines_coldchain!A11:A1009 = F11) * (purchase_order_lines_coldchain!G11:G1009 = E11) * (purchase_order_lines_coldchain!D11:D1009 = D11), purchase_order_lines_coldchain!B$2:B$1000, _xlfn.XLOOKUP(F11,purchase_order_lines_coldchain!A$2:A1009, purchase_order_lines_coldchain!B$2:B1009)), "")} | I11: =G11 & H11 -> PO000116 | J11: LOT-144-000010 | K11: 88 | L11: 88 | M11: 14.25 | N11: 1254 | O11: 1.4 | P11: Supplier_Delivery
A12: MOV0000011 | B12: 45679.886 | C12: Receipt | D12: WH-ABJ-01 | E12: PRD00128 | F12: POL000297 | G12: PO000105 | H12: {=IF(AND(G12="", C12="Receipt"), _xlfn.XLOOKUP(1, (purchase_order_lines_coldchain!A12:A1010 = F12) * (purchase_order_lines_coldchain!G12:G1010 = E12) * (purchase_order_lines_coldchain!D12:D1010 = D12), purchase_order_lines_coldchain!B$2:B$1000, _xlfn.XLOOKUP(F12,purchase_order_lines_coldchain!A$2:A1010, purchase_order_lines_coldchain!B$2:B1010)), "")} | I12: =G12 & H12 -> PO000105 | J12: LOT-128-000011 | K12: 121 | L12: 121 | M12: 11.92 | N12: 1442.32 | O12: 5.8 | P12: Supplier_Delivery
A13: MOV0000012 | B13: 45709.019 | C13: Receipt | D13: WH-PHC-01 | E13: PRD00022 | F13: POL000291 | G13: PO000103 | H13: {=IF(AND(G13="", C13="Receipt"), _xlfn.XLOOKUP(1, (purchase_order_lines_coldchain!A13:A1011 = F13) * (purchase_order_lines_coldchain!G13:G1011 = E13) * (purchase_order_lines_coldchain!D13:D1011 = D13), purchase_order_lines_coldchain!B$2:B$1000, _xlfn.XLOOKUP(F13,purchase_order_lines_coldchain!A$2:A1011, purchase_order_lines_coldchain!B$2:B1011)), "")} | I13: =G13 & H13 -> PO000103 | J13: LOT-022-000012 | K13: 234 | L13: 234 | M13: 1.81 | N13: 423.54 | O13: 3.7 | P13: Supplier_Delivery
... A53: MOV0000052 | B53: 45732.777 | C53: Receipt | D53: WH-LAG-01 | E53: PRD00070 | F53: POL000399 | G53: PO000143 | H53: {=IF(AND(G53="", C53="Receipt"), _xlfn.XLOOKUP(1, (purchase_order_lines_coldchain!A53:A1051 = F53) * (purchase_order_lines_coldchain!G53:G1051 = E53) * (purchase_order_lines_coldchain!D53:D1051 = D53), purchase_order_lines_coldchain!B$2:B$1000, _xlfn.XLOOKUP(F53,purchase_order_lines_coldchain!A$2:A1051, purchase_order_lines_coldchain!B$2:B1051)), "")} | I53: =G53 & H53 -> PO000143 | J53: LOT-070-000052 | K53: 148 | L53: 148 | M53: 5.95 | N53: 880.6 | O53: 0.9 | P53: Supplier_Delivery
A54: MOV0000053 | B54: 45739.14 | C54: Receipt | D54: WH-ABJ-01 | E54: PRD00067 | F54: POL000181 | H54: {=IF(AND(G54="", C54="Receipt"), _xlfn.XLOOKUP(1, (purchase_order_lines_coldchain!A54:A1052 = F54) * (purchase_order_lines_coldchain!G54:G1052 = E54) * (purchase_order_lines_coldchain!D54:D1052 = D54), purchase_order_lines_coldchain!B$2:B$1000, _xlfn.XLOOKUP(F54,purchase_order_lines_coldchain!A$2:A1052, purchase_order_lines_coldchain!B$2:B1052)), "")} -> PO000047 | I54: =G54 & H54 -> PO000047 | J54: LOT-067-000053 | K54: 126 | L54: 126 | M54: 2.58 | N54: 325.08 | O54: 4.9 | P54: Supplier_Delivery
A55: MOV0000054 | B55: 45738.846 | C55: Receipt | D55: WH-ENU-01 | E55: PRD00018 | F55: POL000333 | G55: PO000118 | H55: {=IF(AND(G55="", C55="Receipt"), _xlfn.XLOOKUP(1, (purchase_order_lines_coldchain!A55:A1053 = F55) * (purchase_order_lines_coldchain!G55:G1053 = E55) * (purchase_order_lines_coldchain!D55:D1053 = D55), purchase_order_lines_coldchain!B$2:B$1000, _xlfn.XLOOKUP(F55,purchase_order_lines_coldchain!A$2:A1053, purchase_order_lines_coldchain!B$2:B1053)), "")} | I55: =G55 & H55 -> PO000118 | J55: LOT-018-000054 | K55: 40 | L55: 40 | M55: 12.33 | N55: 493.2 | O55: 3.6 | P55: Supplier_Delivery
A56: MOV0000055 | B56: 45712.733 | C56: Receipt | D56: WH-KAD-01 | E56: PRD00098 | F56: POL000279 | G56: PO000099 | H56: {=IF(AND(G56="", C56="Receipt"), _xlfn.XLOOKUP(1, (purchase_order_lines_coldchain!A56:A1054 = F56) * (purchase_order_lines_coldchain!G56:G1054 = E56) * (purchase_order_lines_coldchain!D56:D1054 = D56), purchase_order_lines_coldchain!B$2:B$1000, _xlfn.XLOOKUP(F56,purchase_order_lines_coldchain!A$2:A1054, purchase_order_lines_coldchain!B$2:B1054)), "")} | I56: =G56 & H56 -> PO000099 | J56: LOT-098-000055 | K56: 11 | L56: 11 | M56: 1.8 | N56: 19.8 | O56: 7.7 | P56: Supplier_Delivery
A57: MOV0000056 | B57: 45711.858 | C57: Receipt | D57: WH-KAD-01 | E57: PRD00098 | F57: POL000281 | G57: PO000099 | H57: {=IF(AND(G57="", C57="Receipt"), _xlfn.XLOOKUP(1, (purchase_order_lines_coldchain!A57:A1055 = F57) * (purchase_order_lines_coldchain!G57:G1055 = E57) * (purchase_order_lines_coldchain!D57:D1055 = D57), purchase_order_lines_coldchain!B$2:B$1000, _xlfn.XLOOKUP(F57,purchase_order_lines_coldchain!A$2:A1055, purchase_order_lines_coldchain!B$2:B1055)), "")} | I57: =G57 & H57 -> PO000099 | J57: LOT-098-000056 | K57: 56 | L57: 56 | M57: 1.74 | N57: 97.44 | O57: 3.7 | P57: Supplier_Delivery
A58: MOV0000057 | B58: 45691.505 | C58: Receipt | D58: WH-ABJ-01 | E58: PRD00161 | F58: POL000001 | G58: PO000001 | H58: {=IF(AND(G58="", C58="Receipt"), _xlfn.XLOOKUP(1, (purchase_order_lines_coldchain!A58:A1056 = F58) * (purchase_order_lines_coldchain!G58:G1056 = E58) * (purchase_order_lines_coldchain!D58:D1056 = D58), purchase_order_lines_coldchain!B$2:B$1000, _xlfn.XLOOKUP(F58,purchase_order_lines_coldchain!A$2:A1056, purchase_order_lines_coldchain!B$2:B1056)), "")} | I58: =G58 & H58 -> PO000001 | J58: LOT-161-000057 | K58: 84 | L58: 84 | M58: 3.75 | N58: 315 | O58: 2.6 | P58: Supplier_Delivery
A59: MOV0000058 | B59: 45721.409 | C59: Receipt | D59: WH-BEN-01 | E59: PRD00146 | F59: POL000186 | G59: PO000066 | H59: {=IF(AND(G59="", C59="Receipt"), _xlfn.XLOOKUP(1, (purchase_order_lines_coldchain!A59:A1057 = F59) * (purchase_order_lines_coldchain!G59:G1057 = E59) * (purchase_order_lines_coldchain!D59:D1057 = D59), purchase_order_lines_coldchain!B$2:B$1000, _xlfn.XLOOKUP(F59,purchase_order_lines_coldchain!A$2:A1057, purchase_order_lines_coldchain!B$2:B1057)), "")} | I59: =G59 & H59 -> PO000066 | J59: LOT-146-000058 | K59: 106 | L59: 106 | M59: 8.46 | N59: 896.76 | O59: 4.1 | P59: Supplier_Delivery
A60: MOV0000059 | B60: 45712.856 | C60: Receipt | D60: WH-ENU-01 | E60: PRD00054 | F60: POL000339 | G60: PO000120 | H60: {=IF(AND(G60="", C60="Receipt"), _xlfn.XLOOKUP(1, (purchase_order_lines_coldchain!A60:A1058 = F60) * (purchase_order_lines_coldchain!G60:G1058 = E60) * (purchase_order_lines_coldchain!D60:D1058 = D60), purchase_order_lines_coldchain!B$2:B$1000, _xlfn.XLOOKUP(F60,purchase_order_lines_coldchain!A$2:A1058, purchase_order_lines_coldchain!B$2:B1058)), "")} | I60: =G60 & H60 -> PO000120 | J60: LOT-054-000059 | K60: 53 | L60: 53 | M60: 1.61 | N60: 85.33 | O60: 5.3 | P60: Supplier_Delivery
A61: MOV0000060 | B61: 45728.248 | C61: Receipt | D61: WH-KAD-01 | E61: PRD00136 | F61: POL000115 | G61: PO000042 | H61: {=IF(AND(G61="", C61="Receipt"), _xlfn.XLOOKUP(1, (purchase_order_lines_coldchain!A61:A1059 = F61) * (purchase_order_lines_coldchain!G61:G1059 = E61) * (purchase_order_lines_coldchain!D61:D1059 = D61), purchase_order_lines_coldchain!B$2:B$1000, _xlfn.XLOOKUP(F61,purchase_order_lines_coldchain!A$2:A1059, purchase_order_lines_coldchain!B$2:B1059)), "")} | I61: =G61 & H61 -> PO000042 | J61: LOT-136-000060 | K61: 163 | L61: 163 | M61: 5.64 | N61: 919.32 | O61: 4.6 | P61: Supplier_Delivery
A62: MOV0000061 | B62: 45733.653 | C62: Receipt | D62: WH-LAG-02 | E62: PRD00005 | F62: POL000112 | G62: PO000041 | H62: {=IF(AND(G62="", C62="Receipt"), _xlfn.XLOOKUP(1, (purchase_order_lines_coldchain!A62:A1060 = F62) * (purchase_order_lines_coldchain!G62:G1060 = E62) * (purchase_order_lines_coldchain!D62:D1060 = D62), purchase_order_lines_coldchain!B$2:B$1000, _xlfn.XLOOKUP(F62,purchase_order_lines_coldchain!A$2:A1060, purchase_order_lines_coldchain!B$2:B1060)), "")} | I62: =G62 & H62 -> PO000041 | J62: LOT-005-000061 | K62: 67 | L62: 67 | M62: 2.15 | N62: 144.05 | O62: 3 | P62: Supplier_Delivery
A63: MOV0000062 | B63: 45668.778 | C63: Receipt | D63: WH-AWK-01 | E63: PRD00178 | F63: POL000006 | G63: PO000003 | H63: {=IF(AND(G63="", C63="Receipt"), _xlfn.XLOOKUP(1, (purchase_order_lines_coldchain!A63:A1061 = F63) * (purchase_order_lines_coldchain!G63:G1061 = E63) * (purchase_order_lines_coldchain!D63:D1061 = D63), purchase_order_lines_coldchain!B$2:B$1000, _xlfn.XLOOKUP(F63,purchase_order_lines_coldchain!A$2:A1061, purchase_order_lines_coldchain!B$2:B1061)), "")} | I63: =G63 & H63 -> PO000003 | J63: LOT-178-000062 | K63: 49 | L63: 49 | M63: 3.96 | N63: 194.04 | O63: 3.5 | P63: Supplier_Delivery
A64: MOV0000063 | B64: 45665.183 | C64: Receipt | D64: WH-ENU-01 | E64: PRD00039 | F64: POL000106 | G64: PO000039 | H64: {=IF(AND(G64="", C64="Receipt"), _xlfn.XLOOKUP(1, (purchase_order_lines_coldchain!A64:A1062 = F64) * (purchase_order_lines_coldchain!G64:G1062 = E64) * (purchase_order_lines_coldchain!D64:D1062 = D64), purchase_order_lines_coldchain!B$2:B$1000, _xlfn.XLOOKUP(F64,purchase_order_lines_coldchain!A$2:A1062, purchase_order_lines_coldchain!B$2:B1062)), "")} | I64: =G64 & H64 -> PO000039 | J64: LOT-039-000063 | K64: 178 | L64: 178 | M64: 4.74 | N64: 843.72 | O64: 1.8 | P64: Supplier_Delivery
A65: MOV0000064 | B65: 45678.658 | C65: Receipt | D65: WH-ABJ-01 | E65: PRD00098 | F65: POL000141 | G65: PO000051 | H65: {=IF(AND(G65="", C65="Receipt"), _xlfn.XLOOKUP(1, (purchase_order_lines_coldchain!A65:A1063 = F65) * (purchase_order_lines_coldchain!G65:G1063 = E65) * (purchase_order_lines_coldchain!D65:D1063 = D65), purchase_order_lines_coldchain!B$2:B$1000, _xlfn.XLOOKUP(F65,purchase_order_lines_coldchain!A$2:A1063, purchase_order_lines_coldchain!B$2:B1063)), "")} | I65: =G65 & H65 -> PO000051 | J65: LOT-098-000064 | K65: 104 | L65: 104 | M65: 1.77 | N65: 184.08 | O65: 5.5 | P65: Supplier_Delivery
A66: MOV0000065 | B66: 45675.423 | C66: Receipt | D66: WH-ENU-01 | E66: PRD00086 | F66: POL000078 | G66: PO000028 | H66: {=IF(AND(G66="", C66="Receipt"), _xlfn.XLOOKUP(1, (purchase_order_lines_coldchain!A66:A1064 = F66) * (purchase_order_lines_coldchain!G66:G1064 = E66) * (purchase_order_lines_coldchain!D66:D1064 = D66), purchase_order_lines_coldchain!B$2:B$1000, _xlfn.XLOOKUP(F66,purchase_order_lines_coldchain!A$2:A1064, purchase_order_lines_coldchain!B$2:B1064)), "")} | I66: =G66 & H66 -> PO000028 | J66: LOT-086-000065 | K66: 117 | L66: 117 | M66: 5.46 | N66: 638.82 | O66: 7.5 | P66: Supplier_Delivery
... A150: MOV0000149 | B150: 45718.148 | C150: Receipt | D150: WH-ABJ-01 | E150: PRD00051 | F150: POL000317 | G150: PO000113 | H150: {=IF(AND(G150="", C150="Receipt"), _xlfn.XLOOKUP(1, (purchase_order_lines_coldchain!A150:A1148 = F150) * (purchase_order_lines_coldchain!G150:G1148 = E150) * (purchase_order_lines_coldchain!D150:D1148 = D150), purchase_order_lines_coldchain!B$2:B$1000, _xlfn.XLOOKUP(F150,purchase_order_lines_coldchain!A$2:A1148, purchase_order_lines_coldchain!B$2:B1148)), "")} | I150: =G150 & H150 -> PO000113 | J150: LOT-051-000149 | K150: 152 | L150: 152 | M150: 1.79 | N150: 272.08 | O150: 7.2 | P150: Supplier_Delivery
A151: MOV0000150 | B151: 45699.84 | C151: Receipt | D151: WH-BEN-01 | E151: PRD00105 | F151: POL000284 | H151: {=IF(AND(G151="", C151="Receipt"), _xlfn.XLOOKUP(1, (purchase_order_lines_coldchain!A151:A1149 = F151) * (purchase_order_lines_coldchain!G151:G1149 = E151) * (purchase_order_lines_coldchain!D151:D1149 = D151), purchase_order_lines_coldchain!B$2:B$1000, _xlfn.XLOOKUP(F151,purchase_order_lines_coldchain!A$2:A1149, purchase_order_lines_coldchain!B$2:B1149)), "")} -> PO000049 | I151: =G151 & H151 -> PO000049 | J151: LOT-105-000150 | K151: 198 | L151: 198 | M151: 8.95 | N151: 1772.1 | O151: 3.4 | P151: Supplier_Delivery
A152: MOV0000151 | B152: 45713.947 | C152: Receipt | D152: WH-LAG-02 | E152: PRD00070 | F152: POL000101 | G152: PO000037 | H152: {=IF(AND(G152="", C152="Receipt"), _xlfn.XLOOKUP(1, (purchase_order_lines_coldchain!A152:A1150 = F152) * (purchase_order_lines_coldchain!G152:G1150 = E152) * (purchase_order_lines_coldchain!D152:D1150 = D152), purchase_order_lines_coldchain!B$2:B$1000, _xlfn.XLOOKUP(F152,purchase_order_lines_coldchain!A$2:A1150, purchase_order_lines_coldchain!B$2:B1150)), "")} | I152: =G152 & H152 -> PO000037 | J152: LOT-070-000151 | K152: 136 | L152: 136 | M152: 5.86 | N152: 796.96 | O152: 8.5 | P152: Supplier_Delivery
A153: MOV0000152 | B153: 45721.933 | C153: Receipt | D153: WH-IBA-01 | E153: PRD00163 | F153: POL000058 | G153: PO000021 | H153: {=IF(AND(G153="", C153="Receipt"), _xlfn.XLOOKUP(1, (purchase_order_lines_coldchain!A153:A1151 = F153) * (purchase_order_lines_coldchain!G153:G1151 = E153) * (purchase_order_lines_coldchain!D153:D1151 = D153), purchase_order_lines_coldchain!B$2:B$1000, _xlfn.XLOOKUP(F153,purchase_order_lines_coldchain!A$2:A1151, purchase_order_lines_coldchain!B$2:B1151)), "")} | I153: =G153 & H153 -> PO000021 | J153: LOT-163-000152 | K153: 18 | L153: 18 | M153: 8.24 | N153: 148.32 | O153: 5.4 | P153: Supplier_Delivery
A154: MOV0000153 | B154: 45701.203 | C154: Receipt | D154: WH-PHC-01 | E154: PRD00051 | F154: POL000134 | G154: PO000049 | H154: {=IF(AND(G154="", C154="Receipt"), _xlfn.XLOOKUP(1, (purchase_order_lines_coldchain!A154:A1152 = F154) * (purchase_order_lines_coldchain!G154:G1152 = E154) * (purchase_order_lines_coldchain!D154:D1152 = D154), purchase_order_lines_coldchain!B$2:B$1000, _xlfn.XLOOKUP(F154,purchase_order_lines_coldchain!A$2:A1152, purchase_order_lines_coldchain!B$2:B1152)), "")} | I154: =G154 & H154 -> PO000049 | J154: LOT-051-000153 | K154: 89 | L154: 89 | M154: 1.71 | N154: 152.19 | O154: 6.9 | P154: Supplier_Delivery
A155: MOV0000154 | B155: 45742.193 | C155: Receipt | D155: WH-ENU-01 | E155: PRD00154 | F155: POL000100 | G155: PO000036 | H155: {=IF(AND(G155="", C155="Receipt"), _xlfn.XLOOKUP(1, (purchase_order_lines_coldchain!A155:A1153 = F155) * (purchase_order_lines_coldchain!G155:G1153 = E155) * (purchase_order_lines_coldchain!D155:D1153 = D155), purchase_order_lines_coldchain!B$2:B$1000, _xlfn.XLOOKUP(F155,purchase_order_lines_coldchain!A$2:A1153, purchase_order_lines_coldchain!B$2:B1153)), "")} | I155: =G155 & H155 -> PO000036 | J155: LOT-154-000154 | K155: 211 | L155: 211 | M155: 15.77 | N155: 3327.47 | O155: 1.7 | P155: Supplier_Delivery
A156: MOV0000155 | B156: 45688.302 | C156: Receipt | D156: WH-KAD-01 | E156: PRD00152 | F156: POL000227 | G156: PO000080 | H156: {=IF(AND(G156="", C156="Receipt"), _xlfn.XLOOKUP(1, (purchase_order_lines_coldchain!A156:A1154 = F156) * (purchase_order_lines_coldchain!G156:G1154 = E156) * (purchase_order_lines_coldchain!D156:D1154 = D156), purchase_order_lines_coldchain!B$2:B$1000, _xlfn.XLOOKUP(F156,purchase_order_lines_coldchain!A$2:A1154, purchase_order_lines_coldchain!B$2:B1154)), "")} | I156: =G156 & H156 -> PO000080 | J156: LOT-152-000155 | K156: 30 | L156: 30 | M156: 7.89 | N156: 236.7 | O156: 2.8 | P156: Supplier_Delivery
A157: MOV0000156 | B157: 45709.18 | C157: Receipt | D157: WH-JOS-01 | E157: PRD00134 | F157: POL000080 | G157: PO000029 | H157: {=IF(AND(G157="", C157="Receipt"), _xlfn.XLOOKUP(1, (purchase_order_lines_coldchain!A157:A1155 = F157) * (purchase_order_lines_coldchain!G157:G1155 = E157) * (purchase_order_lines_coldchain!D157:D1155 = D157), purchase_order_lines_coldchain!B$2:B$1000, _xlfn.XLOOKUP(F157,purchase_order_lines_coldchain!A$2:A1155, purchase_order_lines_coldchain!B$2:B1155)), "")} | I157: =G157 & H157 -> PO000029 | J157: LOT-134-000156 | K157: 69 | L157: 69 | M157: 13.34 | N157: 920.46 | O157: 3.4 | P157: Supplier_Delivery
A158: MOV0000157 | B158: 45678.755 | C158: Receipt | D158: WH-LAG-01 | E158: PRD00033 | F158: POL000005 | G158: PO000002 | H158: {=IF(AND(G158="", C158="Receipt"), _xlfn.XLOOKUP(1, (purchase_order_lines_coldchain!A158:A1156 = F158) * (purchase_order_lines_coldchain!G158:G1156 = E158) * (purchase_order_lines_coldchain!D158:D1156 = D158), purchase_order_lines_coldchain!B$2:B$1000, _xlfn.XLOOKUP(F158,purchase_order_lines_coldchain!A$2:A1156, purchase_order_lines_coldchain!B$2:B1156)), "")} | I158: =G158 & H158 -> PO000002 | J158: LOT-033-000157 | K158: 195 | L158: 195 | M158: 13.16 | N158: 2566.2 | O158: 2.3 | P158: Supplier_Delivery
A159: MOV0000158 | B159: 45686.733 | C159: Receipt | D159: WH-ABJ-01 | E159: PRD00055 | F159: POL000219 | G159: PO000078 | H159: {=IF(AND(G159="", C159="Receipt"), _xlfn.XLOOKUP(1, (purchase_order_lines_coldchain!A159:A1157 = F159) * (purchase_order_lines_coldchain!G159:G1157 = E159) * (purchase_order_lines_coldchain!D159:D1157 = D159), purchase_order_lines_coldchain!B$2:B$1000, _xlfn.XLOOKUP(F159,purchase_order_lines_coldchain!A$2:A1157, purchase_order_lines_coldchain!B$2:B1157)), "")} | I159: =G159 & H159 -> PO000078 | J159: LOT-055-000158 | K159: 135 | L159: 135 | M159: 10.66 | N159: 1439.1 | O159: -16 | P159: Supplier_Delivery
A160: MOV0000159 | B160: 45701.297 | C160: Receipt | D160: WH-PHC-01 | E160: PRD00050 | F160: POL000110 | G160: PO000040 | H160: {=IF(AND(G160="", C160="Receipt"), _xlfn.XLOOKUP(1, (purchase_order_lines_coldchain!A160:A1158 = F160) * (purchase_order_lines_coldchain!G160:G1158 = E160) * (purchase_order_lines_coldchain!D160:D1158 = D160), purchase_order_lines_coldchain!B$2:B$1000, _xlfn.XLOOKUP(F160,purchase_order_lines_coldchain!A$2:A1158, purchase_order_lines_coldchain!B$2:B1158)), "")} | I160: =G160 & H160 -> PO000040 | J160: LOT-050-000159 | K160: 87 | L160: 87 | M160: 15.89 | N160: 1382.43 | O160: 0.8 | P160: Supplier_Delivery
A161: MOV0000160 | B161: 45717.562 | C161: Receipt | D161: WH-KAD-01 | E161: PRD00113 | F161: POL000283 | G161: PO000100 | H161: {=IF(AND(G161="", C161="Receipt"), _xlfn.XLOOKUP(1, (purchase_order_lines_coldchain!A161:A1159 = F161) * (purchase_order_lines_coldchain!G161:G1159 = E161) * (purchase_order_lines_coldchain!D161:D1159 = D161), purchase_order_lines_coldchain!B$2:B$1000, _xlfn.XLOOKUP(F161,purchase_order_lines_coldchain!A$2:A1159, purchase_order_lines_coldchain!B$2:B1159)), "")} | I161: =G161 & H161 -> PO000100 | J161: LOT-113-000160 | K161: 224 | L161: 224 | M161: 5.48 | N161: 1227.52 | O161: 3.1 | P161: Supplier_Delivery
A162: MOV0000161 | B162: 45701.284 | C162: Receipt | D162: WH-IBA-01 | E162: PRD00036 | F162: POL000254 | G162: PO000090 | H162: {=IF(AND(G162="", C162="Receipt"), _xlfn.XLOOKUP(1, (purchase_order_lines_coldchain!A162:A1160 = F162) * (purchase_order_lines_coldchain!G162:G1160 = E162) * (purchase_order_lines_coldchain!D162:D1160 = D162), purchase_order_lines_coldchain!B$2:B$1000, _xlfn.XLOOKUP(F162,purchase_order_lines_coldchain!A$2:A1160, purchase_order_lines_coldchain!B$2:B1160)), "")} | I162: =G162 & H162 -> PO000090 | J162: LOT-036-000161 | K162: 198 | L162: 198 | M162: 12.22 | N162: 2419.56 | O162: -0.7 | P162: Supplier_Delivery
...

Sheet cycle_counts_coldchain
A1: count_id | B1: warehouse_id | C1: product_id | D1: count_date | E1: system_qty | F1: system_qty_Check | G1: counted_qty | H1: variance | I1: variance_check | J1: count_type | K1: counted_by | L1: notes
A2: CC000001 | B2: WH-LAG-02 | C2: PRD00043 | D2: 45774.433 | E2: 0 | F2: =IF(E2=(SUMIFS(stock_movements_coldchain[signed_qty],stock_movements_coldchain[product_id],C2,stock_movements_coldchain[warehouse_id],B2,stock_movements_coldchain[movement_date],"<" &'cycle_counts_coldchain'!D2)),"Pass","Investigate") -> Pass | G2: 0 | H2: 0 | I2: =IF((G2-E2)=H2,"Pass","Investigate") -> Pass | J2: Full | K2: I. Musa | L2: Cold Room Audit
A3: CC000002 | B3: WH-LAG-02 | C3: PRD00039 | D3: 45757.54 | E3: 0 | F3: =IF(E3=(SUMIFS(stock_movements_coldchain[signed_qty],stock_movements_coldchain[product_id],C3,stock_movements_coldchain[warehouse_id],B3,stock_movements_coldchain[movement_date],"<" &'cycle_counts_coldchain'!D3)),"Pass","Investigate") -> Pass | G3: 0 | H3: 0 | I3: =IF((G3-E3)=H3,"Pass","Investigate") -> Pass | J3: Spot | K3: I. Musa | L3: Near Expiry Review
A4: CC000003 | B4: WH-IBA-01 | C4: PRD00048 | D4: 45749.373 | E4: 0 | F4: =IF(E4=(SUMIFS(stock_movements_coldchain[signed_qty],stock_movements_coldchain[product_id],C4,stock_movements_coldchain[warehouse_id],B4,stock_movements_coldchain[movement_date],"<" &'cycle_counts_coldchain'!D4)),"Pass","Investigate") -> Pass | G4: 4 | H4: 4 | I4: =IF((G4-E4)=H4,"Pass","Investigate") -> Pass | J4: Cycle | K4: A. Ibrahim
A5: CC000004 | B5: WH-JOS-01 | C5: PRD00017 | D5: 45774.117 | E5: 0 | F5: =IF(E5=(SUMIFS(stock_movements_coldchain[signed_qty],stock_movements_coldchain[product_id],C5,stock_movements_coldchain[warehouse_id],B5,stock_movements_coldchain[movement_date],"<" &'cycle_counts_coldchain'!D5)),"Pass","Investigate") -> Pass | G5: 0 | H5: 0 | I5: =IF((G5-E5)=H5,"Pass","Investigate") -> Pass | J5: Cycle | K5: F. Adebayo | L5: Cold Room Audit
A6: CC000005 | B6: WH-BEN-01 | C6: PRD00124 | D6: 45689.584 | E6: 0 | F6: =IF(E6=(SUMIFS(stock_movements_coldchain[signed_qty],stock_movements_coldchain[product_id],C6,stock_movements_coldchain[warehouse_id],B6,stock_movements_coldchain[movement_date],"<" &'cycle_counts_coldchain'!D6)),"Pass","Investigate") -> Pass | G6: 0 | H6: 0 | I6: =IF((G6-E6)=H6,"Pass","Investigate") -> Pass | J6: Cycle | K6: I. Musa | L6: Fefo Check
A7: CC000006 | B7: WH-LAG-01 | C7: PRD00092 | D7: 45760.557 | E7: 740 | F7: =IF(E7=(SUMIFS(stock_movements_coldchain[signed_qty],stock_movements_coldchain[product_id],C7,stock_movements_coldchain[warehouse_id],B7,stock_movements_coldchain[movement_date],"<" &'cycle_counts_coldchain'!D7)),"Pass","Investigate") -> Pass | G7: 737 | H7: -3 | I7: =IF((G7-E7)=H7,"Pass","Investigate") -> Pass | J7: Cycle | K7: S. Bello | L7: Cold Room Audit
A8: CC000007 | B8: WH-PHC-01 | C8: PRD00022 | D8: 45678.001 | E8: 0 | F8: =IF(E8=(SUMIFS(stock_movements_coldchain[signed_qty],stock_movements_coldchain[product_id],C8,stock_movements_coldchain[warehouse_id],B8,stock_movements_coldchain[movement_date],"<" &'cycle_counts_coldchain'!D8)),"Pass","Investigate") -> Pass | G8: 3 | H8: 3 | I8: =IF((G8-E8)=H8,"Pass","Investigate") -> Pass | J8: Cycle | K8: I. Musa | L8: Fefo Check
A9: CC000008 | B9: WH-KAD-01 | C9: PRD00062 | D9: 45746.144 | E9: 0 | F9: =IF(E9=(SUMIFS(stock_movements_coldchain[signed_qty],stock_movements_coldchain[product_id],C9,stock_movements_coldchain[warehouse_id],B9,stock_movements_coldchain[movement_date],"<" &'cycle_counts_coldchain'!D9)),"Pass","Investigate") -> Pass | G9: 0 | H9: 0 | I9: =IF((G9-E9)=H9,"Pass","Investigate") -> Pass | J9: Spot | K9: A. Ibrahim
A10: CC000009 | B10: WH-ENU-01 | C10: PRD00138 | D10: 45776.608 | E10: 0 | F10: =IF(E10=(SUMIFS(stock_movements_coldchain[signed_qty],stock_movements_coldchain[product_id],C10,stock_movements_coldchain[warehouse_id],B10,stock_movements_coldchain[movement_date],"<" &'cycle_counts_coldchain'!D10)),"Pass","Investigate") -> Pass | G10: 0 | H10: 0 | I10: =IF((G10-E10)=H10,"Pass","Investigate") -> Pass | J10: Cycle | K10: F. Adebayo | L10: Fefo Check
A11: CC000010 | B11: WH-IBA-01 | C11: PRD00063 | D11: 45743.109 | E11: 0 | F11: =IF(E11=(SUMIFS(stock_movements_coldchain[signed_qty],stock_movements_coldchain[product_id],C11,stock_movements_coldchain[warehouse_id],B11,stock_movements_coldchain[movement_date],"<" &'cycle_counts_coldchain'!D11)),"Pass","Investigate") -> Pass | G11: 0 | H11: 0 | I11: =IF((G11-E11)=H11,"Pass","Investigate") -> Pass | J11: Spot | K11: S. Bello
A12: CC000011 | B12: WH-IBA-01 | C12: PRD00113 | D12: 45725.146 | E12: 0 | F12: =IF(E12=(SUMIFS(stock_movements_coldchain[signed_qty],stock_movements_coldchain[product_id],C12,stock_movements_coldchain[warehouse_id],B12,stock_movements_coldchain[movement_date],"<" &'cycle_counts_coldchain'!D12)),"Pass","Investigate") -> Pass | G12: 2 | H12: 2 | I12: =IF((G12-E12)=H12,"Pass","Investigate") -> Pass | J12: Cycle | K12: S. Bello
A13: CC000012 | B13: WH-KAD-01 | C13: PRD00046 | D13: 45701.228 | E13: 0 | F13: =IF(E13=(SUMIFS(stock_movements_coldchain[signed_qty],stock_movements_coldchain[product_id],C13,stock_movements_coldchain[warehouse_id],B13,stock_movements_coldchain[movement_date],"<" &'cycle_counts_coldchain'!D13)),"Pass","Investigate") -> Pass | G13: 0 | H13: 0 | I13: =IF((G13-E13)=H13,"Pass","Investigate") -> Pass | J13: Full | K13: A. Ibrahim
A14: CC000013 | B14: WH-PHC-01 | C14: PRD00150 | D14: 45707.963 | E14: 0 | F14: =IF(E14=(SUMIFS(stock_movements_coldchain[signed_qty],stock_movements_coldchain[product_id],C14,stock_movements_coldchain[warehouse_id],B14,stock_movements_coldchain[movement_date],"<" &'cycle_counts_coldchain'!D14)),"Pass","Investigate") -> Pass | G14: 0 | H14: 0 | I14: =IF((G14-E14)=H14,"Pass","Investigate") -> Pass | J14: Full | K14: S. Bello | L14: Near Expiry Review
A15: CC000014 | B15: WH-JOS-01 | C15: PRD00049 | D15: 45682.876 | E15: 0 | F15: =IF(E15=(SUMIFS(stock_movements_coldchain[signed_qty],stock_movements_coldchain[product_id],C15,stock_movements_coldchain[warehouse_id],B15,stock_movements_coldchain[movement_date],"<" &'cycle_counts_coldchain'!D15)),"Pass","Investigate") -> Pass | G15: 0 | H15: 0 | I15: =IF((G15-E15)=H15,"Pass","Investigate") -> Pass | J15: Cycle | K15: F. Adebayo | L15: Fefo Check
A16: CC000015 | B16: WH-KAD-01 | C16: PRD00048 | D16: 45682.701 | E16: 0 | F16: =IF(E16=(SUMIFS(stock_movements_coldchain[signed_qty],stock_movements_coldchain[product_id],C16,stock_movements_coldchain[warehouse_id],B16,stock_movements_coldchain[movement_date],"<" &'cycle_counts_coldchain'!D16)),"Pass","Investigate") -> Pass | G16: 0 | H16: 0 | I16: =IF((G16-E16)=H16,"Pass","Investigate") -> Pass | J16: Cycle | K16: A. Ibrahim | L16: Near Expiry Review
A17: CC000016 | B17: WH-AWK-01 | C17: PRD00060 | D17: 45678.722 | E17: 0 | F17: =IF(E17=(SUMIFS(stock_movements_coldchain[signed_qty],stock_movements_coldchain[product_id],C17,stock_movements_coldchain[warehouse_id],B17,stock_movements_coldchain[movement_date],"<" &'cycle_counts_coldchain'!D17)),"Pass","Investigate") -> Pass | G17: 0 | H17: 0 | I17: =IF((G17-E17)=H17,"Pass","Investigate") -> Pass | J17: Spot | K17: I. Musa | L17: Near Expiry Review
A18: CC000017 | B18: WH-IBA-01 | C18: PRD00011 | D18: 45769.399 | E18: 0 | F18: =IF(E18=(SUMIFS(stock_movements_coldchain[signed_qty],stock_movements_coldchain[product_id],C18,stock_movements_coldchain[warehouse_id],B18,stock_movements_coldchain[movement_date],"<" &'cycle_counts_coldchain'!D18)),"Pass","Investigate") -> Pass | G18: 3 | H18: 3 | I18: =IF((G18-E18)=H18,"Pass","Investigate") -> Pass | J18: Cycle | K18: S. Bello | L18: Fefo Check
A19: CC000018 | B19: WH-IBA-01 | C19: PRD00169 | D19: 45718.39 | E19: 0 | F19: =IF(E19=(SUMIFS(stock_movements_coldchain[signed_qty],stock_movements_coldchain[product_id],C19,stock_movements_coldchain[warehouse_id],B19,stock_movements_coldchain[movement_date],"<" &'cycle_counts_coldchain'!D19)),"Pass","Investigate") -> Pass | G19: 0 | H19: 0 | I19: =IF((G19-E19)=H19,"Pass","Investigate") -> Pass | J19: Full | K19: S. Bello | L19: Cold Room Audit
A20: CC000019 | B20: WH-PHC-01 | C20: PRD00097 | D20: 45742.142 | E20: 0 | F20: =IF(E20=(SUMIFS(stock_movements_coldchain[signed_qty],stock_movements_coldchain[product_id],C20,stock_movements_coldchain[warehouse_id],B20,stock_movements_coldchain[movement_date],"<" &'cycle_counts_coldchain'!D20)),"Pass","Investigate") -> Pass | G20: 3 | H20: 3 | I20: =IF((G20-E20)=H20,"Pass","Investigate") -> Pass | J20: Spot | K20: S. Bello | L20: Fefo Check
A21: CC000020 | B21: WH-BEN-01 | C21: PRD00048 | D21: 45739.583 | E21: 0 | F21: =IF(E21=(SUMIFS(stock_movements_coldchain[signed_qty],stock_movements_coldchain[product_id],C21,stock_movements_coldchain[warehouse_id],B21,stock_movements_coldchain[movement_date],"<" &'cycle_counts_coldchain'!D21)),"Pass","Investigate") -> Pass | G21: 0 | H21: 0 | I21: =IF((G21-E21)=H21,"Pass","Investigate") -> Pass | J21: Full | K21: A. Ibrahim | L21: Near Expiry Review
A22: CC000021 | B22: WH-ENU-01 | C22: PRD00022 | D22: 45699.422 | E22: 0 | F22: =IF(E22=(SUMIFS(stock_movements_coldchain[signed_qty],stock_movements_coldchain[product_id],C22,stock_movements_coldchain[warehouse_id],B22,stock_movements_coldchain[movement_date],"<" &'cycle_counts_coldchain'!D22)),"Pass","Investigate") -> Pass | G22: 0 | H22: 0 | I22: =IF((G22-E22)=H22,"Pass","Investigate") -> Pass | J22: Cycle | K22: F. Adebayo
A23: CC000022 | B23: WH-PHC-01 | C23: PRD00056 | D23: 45689.245 | E23: 0 | F23: =IF(E23=(SUMIFS(stock_movements_coldchain[signed_qty],stock_movements_coldchain[product_id],C23,stock_movements_coldchain[warehouse_id],B23,stock_movements_coldchain[movement_date],"<" &'cycle_counts_coldchain'!D23)),"Pass","Investigate") -> Pass | G23: 4 | H23: 4 | I23: =IF((G23-E23)=H23,"Pass","Investigate") -> Pass | J23: Cycle | K23: S. Bello | L23: Near Expiry Review
A24: CC000023 | B24: WH-ENU-01 | C24: PRD00168 | D24: 45682.426 | E24: 0 | F24: =IF(E24=(SUMIFS(stock_movements_coldchain[signed_qty],stock_movements_coldchain[product_id],C24,stock_movements_coldchain[warehouse_id],B24,stock_movements_coldchain[movement_date],"<" &'cycle_counts_coldchain'!D24)),"Pass","Investigate") -> Pass | G24: 0 | H24: 0 | I24: =IF((G24-E24)=H24,"Pass","Investigate") -> Pass | J24: Full | K24: F. Adebayo
A25: CC000024 | B25: WH-LAG-02 | C25: PRD00134 | D25: 45770.458 | E25: 0 | F25: =IF(E25=(SUMIFS(stock_movements_coldchain[signed_qty],stock_movements_coldchain[product_id],C25,stock_movements_coldchain[warehouse_id],B25,stock_movements_coldchain[movement_date],"<" &'cycle_counts_coldchain'!D25)),"Pass","Investigate") -> Pass | G25: 4 | H25: 4 | I25: =IF((G25-E25)=H25,"Pass","Investigate") -> Pass | J25: Spot | K25: I. Musa
A26: CC000025 | B26: WH-LAG-02 | C26: PRD00158 | D26: 45686.351 | E26: 0 | F26: =IF(E26=(SUMIFS(stock_movements_coldchain[signed_qty],stock_movements_coldchain[product_id],C26,stock_movements_coldchain[warehouse_id],B26,stock_movements_coldchain[movement_date],"<" &'cycle_counts_coldchain'!D26)),"Pass","Investigate") -> Pass | G26: 4 | H26: 4 | I26: =IF((G26-E26)=H26,"Pass","Investigate") -> Pass | J26: Full | K26: F. Adebayo | L26: Near Expiry Review
A27: CC000026 | B27: WH-LAG-02 | C27: PRD00035 | D27: 45698.628 | E27: 0 | F27: =IF(E27=(SUMIFS(stock_movements_coldchain[signed_qty],stock_movements_coldchain[product_id],C27,stock_movements_coldchain[warehouse_id],B27,stock_movements_coldchain[movement_date],"<" &'cycle_counts_coldchain'!D27)),"Pass","Investigate") -> Pass | G27: 0 | H27: 0 | I27: =IF((G27-E27)=H27,"Pass","Investigate") -> Pass | J27: Spot | K27: I. Musa | L27: Fefo Check
A28: CC000027 | B28: WH-BEN-01 | C28: PRD00171 | D28: 45773.512 | E28: 75 | F28: =IF(E28=(SUMIFS(stock_movements_coldchain[signed_qty],stock_movements_coldchain[product_id],C28,stock_movements_coldchain[warehouse_id],B28,stock_movements_coldchain[movement_date],"<" &'cycle_counts_coldchain'!D28)),"Pass","Investigate") -> Pass | G28: 78 | H28: 3 | I28: =IF((G28-E28)=H28,"Pass","Investigate") -> Pass | J28: Cycle | K28: F. Adebayo
A29: CC000028 | B29: WH-JOS-01 | C29: PRD00065 | D29: 45731.348 | E29: 0 | F29: =IF(E29=(SUMIFS(stock_movements_coldchain[signed_qty],stock_movements_coldchain[product_id],C29,stock_movements_coldchain[warehouse_id],B29,stock_movements_coldchain[movement_date],"<" &'cycle_counts_coldchain'!D29)),"Pass","Investigate") -> Pass | G29: 2 | H29: 2 | I29: =IF((G29-E29)=H29,"Pass","Investigate") -> Pass | J29: Full | K29: A. Ibrahim | L29: Fefo Check
A30: CC000029 | B30: WH-JOS-01 | C30: PRD00022 | D30: 45749.201 | E30: 0 | F30: =IF(E30=(SUMIFS(stock_movements_coldchain[signed_qty],stock_movements_coldchain[product_id],C30,stock_movements_coldchain[warehouse_id],B30,stock_movements_coldchain[movement_date],"<" &'cycle_counts_coldchain'!D30)),"Pass","Investigate") -> Pass | G30: 0 | H30: 0 | I30: =IF((G30-E30)=H30,"Pass","Investigate") -> Pass | J30: Cycle | K30: I. Musa | L30: Fefo Check
A31: CC000030 | B31: WH-LAG-02 | C31: PRD00031 | D31: 45752.887 | E31: 0 | F31: =IF(E31=(SUMIFS(stock_movements_coldchain[signed_qty],stock_movements_coldchain[product_id],C31,stock_movements_coldchain[warehouse_id],B31,stock_movements_coldchain[movement_date],"<" &'cycle_counts_coldchain'!D31)),"Pass","Investigate") -> Pass | G31: 3 | H31: 3 | I31: =IF((G31-E31)=H31,"Pass","Investigate") -> Pass | J31: Cycle | K31: I. Musa | L31: Cold Room Audit
A32: CC000031 | B32: WH-PHC-01 | C32: PRD00034 | D32: 45772.913 | E32: 0 | F32: =IF(E32=(SUMIFS(stock_movements_coldchain[signed_qty],stock_movements_coldchain[product_id],C32,stock_movements_coldchain[warehouse_id],B32,stock_movements_coldchain[movement_date],"<" &'cycle_counts_coldchain'!D32)),"Pass","Investigate") -> Pass | G32: 0 | H32: 0 | I32: =IF((G32-E32)=H32,"Pass","Investigate") -> Pass | J32: Full | K32: F. Adebayo | L32: Near Expiry Review
A33: CC000032 | B33: WH-LAG-01 | C33: PRD00074 | D33: 45749.214 | E33: 0 | F33: =IF(E33=(SUMIFS(stock_movements_coldchain[signed_qty],stock_movements_coldchain[product_id],C33,stock_movements_coldchain[warehouse_id],B33,stock_movements_coldchain[movement_date],"<" &'cycle_counts_coldchain'!D33)),"Pass","Investigate") -> Pass | G33: 0 | H33: 0 | I33: =IF((G33-E33)=H33,"Pass","Investigate") -> Pass | J33: Cycle | K33: F. Adebayo | L33: Cold Room Audit
A34: CC000033 | B34: WH-LAG-02 | C34: PRD00154 | D34: 45752.058 | E34: 0 | F34: =IF(E34=(SUMIFS(stock_movements_coldchain[signed_qty],stock_movements_coldchain[product_id],C34,stock_movements_coldchain[warehouse_id],B34,stock_movements_coldchain[movement_date],"<" &'cycle_counts_coldchain'!D34)),"Pass","Investigate") -> Pass | G34: 1 | H34: 1 | I34: =IF((G34-E34)=H34,"Pass","Investigate") -> Pass | J34: Spot | K34: S. Bello | L34: Cold Room Audit
A35: CC000034 | B35: WH-PHC-01 | C35: PRD00092 | D35: 45709.022 | E35: 0 | F35: =IF(E35=(SUMIFS(stock_movements_coldchain[signed_qty],stock_movements_coldchain[product_id],C35,stock_movements_coldchain[warehouse_id],B35,stock_movements_coldchain[movement_date],"<" &'cycle_counts_coldchain'!D35)),"Pass","Investigate") -> Pass | G35: 1 | H35: 1 | I35: =IF((G35-E35)=H35,"Pass","Investigate") -> Pass | J35: Cycle | K35: F. Adebayo | L35: Near Expiry Review
A36: CC000035 | B36: WH-BEN-01 | C36: PRD00123 | D36: 45718.224 | E36: 0 | F36: =IF(E36=(SUMIFS(stock_movements_coldchain[signed_qty],stock_movements_coldchain[product_id],C36,stock_movements_coldchain[warehouse_id],B36,stock_movements_coldchain[movement_date],"<" &'cycle_counts_coldchain'!D36)),"Pass","Investigate") -> Pass | G36: 0 | H36: 0 | I36: =IF((G36-E36)=H36,"Pass","Investigate") -> Pass | J36: Full | K36: A. Ibrahim | L36: Near Expiry Review
A37: CC000036 | B37: WH-PHC-01 | C37: PRD00104 | D37: 45695.482 | E37: 0 | F37: =IF(E37=(SUMIFS(stock_movements_coldchain[signed_qty],stock_movements_coldchain[product_id],C37,stock_movements_coldchain[warehouse_id],B37,stock_movements_coldchain[movement_date],"<" &'cycle_counts_coldchain'!D37)),"Pass","Investigate") -> Pass | G37: 0 | H37: 0 | I37: =IF((G37-E37)=H37,"Pass","Investigate") -> Pass | J37: Spot | K37: A. Ibrahim | L37: Cold Room Audit
A38: CC000037 | B38: WH-LAG-01 | C38: PRD00112 | D38: 45728.137 | E38: 0 | F38: =IF(E38=(SUMIFS(stock_movements_coldchain[signed_qty],stock_movements_coldchain[product_id],C38,stock_movements_coldchain[warehouse_id],B38,stock_movements_coldchain[movement_date],"<" &'cycle_counts_coldchain'!D38)),"Pass","Investigate") -> Pass | G38: 0 | H38: 0 | I38: =IF((G38-E38)=H38,"Pass","Investigate") -> Pass | J38: Cycle | K38: F. Adebayo | L38: Near Expiry Review
A39: CC000038 | B39: WH-AWK-01 | C39: PRD00100 | D39: 45706.201 | E39: 0 | F39: =IF(E39=(SUMIFS(stock_movements_coldchain[signed_qty],stock_movements_coldchain[product_id],C39,stock_movements_coldchain[warehouse_id],B39,stock_movements_coldchain[movement_date],"<" &'cycle_counts_coldchain'!D39)),"Pass","Investigate") -> Pass | G39: 4 | H39: 4 | I39: =IF((G39-E39)=H39,"Pass","Investigate") -> Pass | J39: Spot | K39: I. Musa
A40: CC000039 | B40: WH-IBA-01 | C40: PRD00037 | D40: 45694.438 | E40: 0 | F40: =IF(E40=(SUMIFS(stock_movements_coldchain[signed_qty],stock_movements_coldchain[product_id],C40,stock_movements_coldchain[warehouse_id],B40,stock_movements_coldchain[movement_date],"<" &'cycle_counts_coldchain'!D40)),"Pass","Investigate") -> Pass | G40: 1 | H40: 1 | I40: =IF((G40-E40)=H40,"Pass","Investigate") -> Pass | J40: Full | K40: F. Adebayo | L40: Cold Room Audit
...

Sheet temperature_logs_coldchain
A1: log_id | B1: warehouse_id | C1: warehouse_name | D1: log_time | E1: setpoint_c | F1: temperature_c | G1: humidity_pct | H1: sensor_status | I1: excursion_flag
A2: TL000001 | B2: WH-LAG-01 | C2: Lagos North Cold Hub | D2: 45737.915 | E2: 3 | F2: 3.1 | G2: 64 | H2: OK | I2: N
A3: TL000002 | B3: WH-LAG-01 | C3: Lagos North Cold Hub | D3: 45746.297 | E3: 3 | F3: 2 | G3: 61 | H3: OK | I3: N
A4: TL000003 | B4: WH-LAG-01 | C4: Lagos North Cold Hub | D4: 45766.742 | E4: 3 | F4: 3.1 | G4: 83 | H4: OK | I4: N
A5: TL000004 | B5: WH-LAG-01 | C5: Lagos North Cold Hub | D5: 45765.852 | E5: 3 | F5: 3.1 | G5: 66 | H5: OK | I5: N
A6: TL000005 | B6: WH-LAG-01 | C6: Lagos North Cold Hub | D6: 45716.798 | E6: 2 | F6: 3.3 | G6: 71 | H6: WARN | I6: Y
A7: TL000006 | B7: WH-LAG-01 | C7: Lagos North Cold Hub | D7: 45663.513 | E7: 4 | F7: 3 | G7: 51 | H7: OK | I7: N
A8: TL000007 | B8: WH-LAG-01 | C8: Lagos North Cold Hub | D8: 45738.932 | E8: 3 | F8: -1.2 | G8: 55 | H8: OK | I8: Y
A9: TL000008 | B9: WH-LAG-01 | C9: Lagos North Cold Hub | D9: 45692.931 | E9: 3 | F9: 2.8 | G9: 57 | H9: OK | I9: N
A10: TL000009 | B10: WH-LAG-01 | C10: Lagos North Cold Hub | D10: 45670.934 | E10: 4 | F10: 3.9 | G10: 53 | H10: OK | I10: N
A11: TL000010 | B11: WH-LAG-01 | C11: Lagos North Cold Hub | D11: 45675.014 | E11: 2 | F11: 0.9 | G11: 70 | H11: OK | I11: N
A12: TL000011 | B12: WH-LAG-01 | C12: Lagos North Cold Hub | D12: 45703.248 | E12: 3 | F12: 8.5 | G12: 57 | H12: WARN | I12: Y
A13: TL000012 | B13: WH-LAG-01 | C13: Lagos North Cold Hub | D13: 45728.483 | E13: 4 | F13: 4.1 | G13: 62 | H13: WARN | I13: Y
... A241: TL000240 | B241: WH-AWK-01 | C241: Awka Micro Hub | D241: 45758.735 | E241: 2 | F241: 2.1 | G241: 64 | H241: OK | I241: N

Sheet Purchase_Order_tracking_sheet
A1: po_line_id | B1: product_id | C1: supplier_id | D1: expected_delivery_day | E1: ordered_qty | F1: received_qty | G1: delivery_status
A2: POL000001 | B2: PRD00161 | C2: SUP00061 | D2: 45690 | E2: 85 | F2: 84 | G2: =IF(E2-F2 <> 0, TEXT(F2/E2, "0%") & " of goods arrived", IF(E2=F2, "All goods arrived", "All goods missing")) -> 99% of goods arrived
A3: POL000002 | B3: PRD00161 | C3: SUP00061 | D3: 45690 | E3: 96 | F3: 92 | G3: =IF(E3-F3 <> 0, TEXT(F3/E3, "0%") & " of goods arrived", IF(E3=F3, "All goods arrived", "All goods missing")) -> 96% of goods arrived
A4: POL000003 | B4: PRD00161 | C4: SUP00061 | D4: 45690 | E4: 169 | F4: 144 | G4: =IF(E4-F4 <> 0, TEXT(F4/E4, "0%") & " of goods arrived", IF(E4=F4, "All goods arrived", "All goods missing")) -> 85% of goods arrived
A5: POL000004 | B5: PRD00067 | C5: SUP00101 | D5: 45677 | E5: 144 | F5: 0 | G5: =IF(E5-F5 <> 0, TEXT(F5/E5, "0%") & " of goods arrived", IF(E5=F5, "All goods arrived", "All goods missing")) -> 0% of goods arrived
A6: POL000005 | B6: PRD00033 | C6: SUP00101 | D6: 45677 | E6: 237 | F6: 195 | G6: =IF(E6-F6 <> 0, TEXT(F6/E6, "0%") & " of goods arrived", IF(E6=F6, "All goods arrived", "All goods missing")) -> 82% of goods arrived
A7: POL000006 | B7: PRD00178 | C7: SUP00089 | D7: 45668 | E7: 64 | F7: 49 | G7: =IF(E7-F7 <> 0, TEXT(F7/E7, "0%") & " of goods arrived", IF(E7=F7, "All goods arrived", "All goods missing")) -> 77% of goods arrived
A8: POL000007 | B8: PRD00011 | C8: SUP00089 | D8: 45668 | E8: 156 | F8: 121 | G8: =IF(E8-F8 <> 0, TEXT(F8/E8, "0%") & " of goods arrived", IF(E8=F8, "All goods arrived", "All goods missing")) -> 78% of goods arrived
A9: POL000008 | B9: PRD00007 | C9: SUP00004 | D9: 45686 | E9: 105 | F9: 93 | G9: =IF(E9-F9 <> 0, TEXT(F9/E9, "0%") & " of goods arrived", IF(E9=F9, "All goods arrived", "All goods missing")) -> 89% of goods arrived
A10: POL000009 | B10: PRD00058 | C10: SUP00004 | D10: 45686 | E10: 104 | F10: 85 | G10: =IF(E10-F10 <> 0, TEXT(F10/E10, "0%") & " of goods arrived", IF(E10=F10, "All goods arrived", "All goods missing")) -> 82% of goods arrived
A11: POL000010 | B11: PRD00141 | C11: SUP00004 | D11: 45686 | E11: 96 | F11: 93 | G11: =IF(E11-F11 <> 0, TEXT(F11/E11, "0%") & " of goods arrived", IF(E11=F11, "All goods arrived", "All goods missing")) -> 97% of goods arrived
A12: POL000011 | B12: PRD00170 | C12: SUP00059 | D12: 45691 | E12: 29 | F12: 0 | G12: =IF(E12-F12 <> 0, TEXT(F12/E12, "0%") & " of goods arrived", IF(E12=F12, "All goods arrived", "All goods missing")) -> 0% of goods arrived
A13: POL000012 | B13: PRD00147 | C13: SUP00059 | D13: 45691 | E13: 130 | F13: 113 | G13: =IF(E13-F13 <> 0, TEXT(F13/E13, "0%") & " of goods arrived", IF(E13=F13, "All goods arrived", "All goods missing")) -> 87% of goods arrived
... A421: POL000420 | B421: PRD00064 | C421: SUP00117 | D421: 45690 | E421: 123 | F421: 114 | G421: =IF(E421-F421 <> 0, TEXT(F421/E421, "0%") & " of goods arrived", IF(E421=F421, "All goods arrived", "All goods missing")) -> 93% of goods arrived

Sheet Warehouse_Transfer_Log
A1: reference_id | B1: Moved_quantity | C1: Received_quantity | D1: Shrinkage Check
A2: XFER-000601 | B2: 1 | C2: 1 | D2: =IF(B2=C2, "No Shrinkage Detected", "Shrinkage Detected") -> No Shrinkage Detected
A3: XFER-000603 | B3: 4 | C3: 4 | D3: =IF(B3=C3, "No Shrinkage Detected", "Shrinkage Detected") -> No Shrinkage Detected
A4: XFER-000605 | B4: 5 | C4: 5 | D4: =IF(B4=C4, "No Shrinkage Detected", "Shrinkage Detected") -> No Shrinkage Detected
A5: XFER-000607 | B5: 2 | C5: 2 | D5: =IF(B5=C5, "No Shrinkage Detected", "Shrinkage Detected") -> No Shrinkage Detected
A6: XFER-000609 | B6: 1 | C6: 1 | D6: =IF(B6=C6, "No Shrinkage Detected", "Shrinkage Detected") -> No Shrinkage Detected
A7: XFER-000611 | B7: 7 | C7: 7 | D7: =IF(B7=C7, "No Shrinkage Detected", "Shrinkage Detected") -> No Shrinkage Detected
A8: XFER-000613 | B8: 5 | C8: 5 | D8: =IF(B8=C8, "No Shrinkage Detected", "Shrinkage Detected") -> No Shrinkage Detected
A9: XFER-000615 | B9: 7 | C9: 7 | D9: =IF(B9=C9, "No Shrinkage Detected", "Shrinkage Detected") -> No Shrinkage Detected
A10: XFER-000617 | B10: 4 | C10: 4 | D10: =IF(B10=C10, "No Shrinkage Detected", "Shrinkage Detected") -> No Shrinkage Detected
A11: XFER-000619 | B11: 3 | C11: 3 | D11: =IF(B11=C11, "No Shrinkage Detected", "Shrinkage Detected") -> No Shrinkage Detected
A12: XFER-000621 | B12: 7 | C12: 7 | D12: =IF(B12=C12, "No Shrinkage Detected", "Shrinkage Detected") -> No Shrinkage Detected
A13: XFER-000623 | B13: 4 | C13: 4 | D13: =IF(B13=C13, "No Shrinkage Detected", "Shrinkage Detected") -> No Shrinkage Detected
... A16: XFER-000629 | B16: 2 | C16: 2 | D16: =IF(B16=C16, "No Shrinkage Detected", "Shrinkage Detected") -> No Shrinkage Detected

Sheet Warehouse_Writeoff_Summary
A1: warehouse_id | B1: total_qty | C1: damaged_write_off_qty | D1: temprature_write_off_qty
A2: WH-ABJ-01 | B2: 5341 | C2: 14 | D2: 0
A3: WH-IBA-01 | B3: 4517 | C3: 2 | D3: 17
A4: WH-PHC-01 | B4: 4212 | C4: 4 | D4: 4
A5: WH-KAD-01 | B5: 3790 | C5: 0 | D5: 1
A6: WH-BEN-01 | B6: 3568 | C6: 9 | D6: 0
A7: WH-ENU-01 | B7: 3563 | C7: 0 | D7: 4
A8: WH-LAG-01 | B8: 3106 | C8: 7 | D8: 4
A9: WH-AWK-01 | B9: 2906 | C9: 4 | D9: 2
A10: WH-JOS-01 | B10: 2638 | C10: 4 | D10: 0
A11: WH-LAG-02 | B11: 2557 | C11: 0 | D11: 4

Sheet Warehouse_Health_Status_Report
A1: warehouse_id | B1: Warning_count | C1: Offline_count
